<?xml version="1.0" encoding="UTF-8"?>
<!-- Generated by org.testng.reporters.JUnitReportReporter -->
<testsuite hostname="ASUS" name="tvs.proj.testng.AppTest" tests="1" failures="1" timestamp="6 Apr 2016 13:50:58 GMT" time="0,001" errors="0">
  <testcase name="test" time="0,001" classname="tvs.proj.testng.AppTest">
    <failure type="org.testng.TestException" message="
Expected exception tvs.proj.testng.exceptions.InvalidOperationException but got org.testng.TestException: 
Method AppTest.test()[pri:0, instance:tvs.proj.testng.AppTest@2f686d1f] should have thrown an exception of class tvs.proj.testng.exceptions.InvalidOperationException">
      <![CDATA[org.testng.TestException: 
Expected exception tvs.proj.testng.exceptions.InvalidOperationException but got org.testng.TestException: 
Method AppTest.test()[pri:0, instance:tvs.proj.testng.AppTest@2f686d1f] should have thrown an exception of class tvs.proj.testng.exceptions.InvalidOperationException
	at org.testng.internal.Invoker.handleInvocationResults(Invoker.java:1459)
	at org.testng.internal.Invoker.invokeTestMethods(Invoker.java:1222)
	at org.testng.internal.TestMethodWorker.invokeTestMethods(TestMethodWorker.java:127)
	at org.testng.internal.TestMethodWorker.run(TestMethodWorker.java:111)
	at org.testng.TestRunner.privateRun(TestRunner.java:758)
	at org.testng.TestRunner.run(TestRunner.java:613)
	at org.testng.SuiteRunner.runTest(SuiteRunner.java:334)
	at org.testng.SuiteRunner.runSequentially(SuiteRunner.java:329)
	at org.testng.SuiteRunner.privateRun(SuiteRunner.java:291)
	at org.testng.SuiteRunner.run(SuiteRunner.java:240)
	at org.testng.SuiteRunnerWorker.runSuite(SuiteRunnerWorker.java:53)
	at org.testng.SuiteRunnerWorker.run(SuiteRunnerWorker.java:87)
	at org.testng.TestNG.runSuitesSequentially(TestNG.java:1137)
	at org.testng.TestNG.runSuitesLocally(TestNG.java:1062)
	at org.testng.TestNG.run(TestNG.java:974)
	at org.apache.maven.surefire.testng.TestNGExecutor.run(TestNGExecutor.java:77)
	at org.apache.maven.surefire.testng.TestNGDirectoryTestSuite.execute(TestNGDirectoryTestSuite.java:110)
	at org.apache.maven.surefire.testng.TestNGProvider.invoke(TestNGProvider.java:106)
	at sun.reflect.NativeMethodAccessorImpl.invoke0(Native Method)
	at sun.reflect.NativeMethodAccessorImpl.invoke(NativeMethodAccessorImpl.java:62)
	at sun.reflect.DelegatingMethodAccessorImpl.invoke(DelegatingMethodAccessorImpl.java:43)
	at java.lang.reflect.Method.invoke(Method.java:497)
	at org.apache.maven.surefire.util.ReflectionUtils.invokeMethodWithArray(ReflectionUtils.java:189)
	at org.apache.maven.surefire.booter.ProviderFactory$ProviderProxy.invoke(ProviderFactory.java:165)
	at org.apache.maven.surefire.booter.ProviderFactory.invokeProvider(ProviderFactory.java:85)
	at org.apache.maven.surefire.booter.ForkedBooter.runSuitesInProcess(ForkedBooter.java:115)
	at org.apache.maven.surefire.booter.ForkedBooter.main(ForkedBooter.java:75)
Caused by: org.testng.TestException: 
Method AppTest.test()[pri:0, instance:tvs.proj.testng.AppTest@2f686d1f] should have thrown an exception of class tvs.proj.testng.exceptions.InvalidOperationException
	at org.testng.internal.Invoker.handleInvocationResults(Invoker.java:1485)
	at org.testng.internal.Invoker.invokeMethod(Invoker.java:740)
	at org.testng.internal.Invoker.invokeTestMethod(Invoker.java:883)
	at org.testng.internal.Invoker.invokeTestMethods(Invoker.java:1208)
	... 25 more
]]>
    </failure>
  </testcase>
</testsuite>
